Workbook

Sheet Resultados
A1: ProductId | B1: Name | C1: ProductDescription | D1: Bullet | E1: Code
A2: =VLOOKUP(B2,Sheet1!A:B,2,FALSE) -> 129 | B2: Conjunto de pijama para niña con camiseta y short | C2: Este conjunto de pijama para niñas es una selección perfecta para las noches placenteras. Elaborado en algodón, ofrece suavidad y transpirabilidad para un descanso cómodo y relajante. La camiseta de manga corta con cuello redondo proporciona comodidad máxima, mientras el pantalón corto ajustable tiene elástico y lazo para un encaje perfecto. | D2: Material de algodón: Ideal para un descanso fresco y suave Camiseta práctica: Manga corta y cuello redondo para mayor confort Ajuste cómodo: Pantalón corto con elástico y lazo funcional | E2: <body><h2>Conjunto de pijama para niña con camiseta y short</h2><br/><p>Este conjunto de pijama para niñas es una selección perfecta para las noches placenteras. Elaborado en algodón, ofrece suavidad y transpirabilidad para un descanso cómodo y relajante.</p><br/><ul><li>Material de algodón: Ideal para un descanso fresco y suave</li><li>Camiseta práctica: Manga corta y cuello redondo proporciona comodidad máxima</li><li>Ajuste cómodo: Pantalón corto ajustable, con elástico y lazo funcional</li></ul></body>
A3: =VLOOKUP(B3,Sheet1!A:B,2,FALSE) -> 131 | B3: Salida de baño de vestido corto | C3: Disfruta de la frescura de tus día de playa o piscina con nuestra salida de baño tipo vestido de silueta amplia con lazo para ajustar en cintura. Tiene mangas con una abertura en el hombro que le da movimiento para mayor comodidad y frescura, adicional tiene aberturas en los costados de la parte inferior para mayor comodidad de movimiento. Su escote profundo en V. Esta elaborada en algodón sin elastomero.<br><strong>Cuidados de la prenda:</strong><br>_x000D_ - Lavar a mano con agua fría máx. 30º.<br>_x000D_ - No usar blanqueador ni dejar en remojo.<br>_x000D_ - No lavar en seco.<br>_x000D_ - Secar colgado a la sombra.<br>_x000D_ - No planchar ni usar secadora.<br>_x000D_ - No retorcer.<br>_x000D_ <strong>Sugerencias adicionales:</strong><br>_x000D_ 1. Enjuagar después de usar.<br>_x000D_ 2. No usar suavizante.<br>_x000D_ 3. Evitar el secado directo al sol.<br>_x000D_ 4. Almacenar en lugar seco y ventilado.<br> | D3: Silueta amplia para mayor comodidad Lazo ajustable para cintura Aberturas en mangas y costados para movimiento | E3: <body><h2>Salida de baño de vestido corto</h2><br/><p style='text-align:justify'><span style='font-size:18px'>Disfruta de la frescura de tus día de playa o piscina con nuestra salida de baño tipo vestido de silueta amplia con lazo para ajustar en cintura. Tiene mangas con una abertura en el hombro que le da movimiento para mayor comodidad y frescura, adicional tiene aberturas en los costados de la parte inferior para mayor comodidad de movimiento. Su escote profundo en V. Esta elaborada en algodón sin elastomero.</span><br/><strong>Cuidados de la prenda:</strong><br/>_x000D_ - Lavar a mano con agua fría máx. 30º.<br/>_x000D_ - No usar blanqueador ni dejar en remojo.<br/>_x000D_ - No lavar en seco.<br/>_x000D_ - Secar colgado a la sombra.<br/>_x000D_ - No planchar ni usar secadora.<br/>_x000D_ - No retorcer.<br/>_x000D_ <strong>Sugerencias adicionales:</strong><br/>_x000D_ 1. Enjuagar después de usar.<br/>_x000D_ 2. No usar suavizante.<br/>_x000D_ 3. Evitar el secado directo al sol.<br/>_x000D_ 4. Almacenar en lugar seco y ventilado.</p></body>
A4: =VLOOKUP(B4,Sheet1!A:B,2,FALSE) -> 132 | B4: Top con copas seamless paquete x2 | C4: Este top, diseñado con tecnología seamless, se ajusta suavemente al cuerpo sin dejar marcas. Su espalda deportiva ofrece libertad de movimiento, siendo ideal para actividades cotidianas. Perfecto para el día a día activo! | D4: Tecnología seamless: Adaptabilidad y confort sin costuras. Espalda deportiva: Versatilidad para cualquier actividad. Diseño sin copas: Sencillez y ligereza. | E4: <body><h2>Top con copas seamless paquete x2</h2><br/><p style='text-align:justify'><span style='font-size:18px'>Este top, diseñado con tecnología seamless, se ajusta suavemente al cuerpo sin dejar marcas. Su espalda deportiva ofrece libertad de movimiento, siendo ideal para actividades cotidianas.</span><strong style='font-size:18px'>Perfecto para el día a día activo!</strong></p><br/><p><strong>Características:</strong></p><ul><li>Tecnología seamless: Adaptabilidad y confort sin costuras.</li><li>Espalda deportiva: Versatilidad para cualquier actividad.</li><li>Diseño sin copas: Sencillez y ligereza.</li></ul></body>
A5: =VLOOKUP(B5,Sheet1!A:B,2,FALSE) -> 133 | B5: Panty tipo bóxer en algodón paquete x3 para niñas | C5: Proporciona comodidad y estilo a las jóvenes con nuestro panty tipo bóxer de algodón. Cuenta con un elástico delgado en la cintura para un ajuste suave y cómodo, brindando la suavidad y simplicidad que las niñas necesitan para sentirse bien en todo momento.<br><br>_x000D_ <strong>Características:</strong><br>_x000D_ <strong>Material:</strong> Algodón.<br>_x000D_ <strong>Diseño:</strong> Tipo bóxer.<br>_x000D_ <strong>Cuidados:</strong> Lavado a mano recomendado para conservar la suavidad. | D5: Silueta ajustada que realza las curvas Escote cruzado en el frente con canal Cargaderas ajustables para mejor ajuste | E5: <body><h2>Panty tipo bóxer en algodón paquete x3 para niñas</h2><br/><p>Proporciona comodidad y estilo a las jóvenes con nuestro panty tipo bóxer de algodón. Cuenta con un elástico delgado en la cintura para un ajuste suave y cómodo, brindando la suavidad y simplicidad que las niñas necesitan para sentirse bien en todo momento.</p><br/><p><strong>Características:</strong></p><ul><li><strong>Material:</strong> Algodón.</li><li><strong>Diseño:</strong> Tipo bóxer.</li></ul><p><strong>Cuidados:</strong> Lavado a mano recomendado para conservar la suavidad.</p></body>
A6: =VLOOKUP(B6,Sheet1!A:B,2,FALSE) -> 134 | B6: Bóxer microfibra corte láser paquete x2 | C6: Experimenta la comodidad definitiva con nuestro bóxer de microfibra con corte láser. Diseñado para ofrecer frescura y flexibilidad durante todo el día, este pack de 10 bóxers es perfecto para quienes buscan comodidad y estilo.<br>_x000D_ <strong>Características destacadas:</strong><br>_x000D_ <strong>Microfibra Fresca:</strong> Suave y ligera, ideal para un uso prolongado.<br>_x000D_ <strong>Corte Láser:</strong> Sin costuras visibles, lo que garantiza un ajuste sin marcas.<br>_x000D_ <strong>Cobertura Completa:</strong> Diseño que ofrece un ajuste cómodo y favorecedor.<br>_x000D_ <strong>Detalles Elegantes:</strong> Tonos suaves que brindan un toque de discreta elegancia.strong>Cuidados de la prenda:</strong><br>_x000D_ - Lavar a mano con agua fría para mantener la calidad.<br>_x000D_ - Evitar blanqueador, remojo y lavado en seco.<br>_x000D_ - Secar colgado y a la sombra, sin retorcer ni usar secadora.<br>_x000D_ <strong>Sugerencias adicionales:</strong><br>_x000D_ 1. Al lavar, usar detergente suave y evitar fricción.<br>_x000D_ 2. Evitar superficies ásperas y almacenar en lugar fresco y seco. | D6: Silueta ajustada que realza las curvas Escote cruzado en el frente con canal Cargaderas ajustables para mejor ajuste | E6: <body><h2><strong style='font-size:24px'>Bóxer microfibra corte láser paquete x2</strong></h2><br/><p style='text-align:justify'><span style='font-size:18px'>Experimenta la comodidad definitiva con nuestro bóxer de microfibra con corte láser. Diseñado para ofrecer frescura y flexibilidad durante todo el día, este pack de 10 bóxers es perfecto para quienes buscan comodidad y estilo.</span></p><br/><p style='text-align:center'><strong>Características destacadas:</strong></p><ul><li><strong>Microfibra Fresca:</strong> Suave y ligera, ideal para un uso prolongado.</li><li><strong>Corte Láser:</strong> Sin costuras visibles, lo que garantiza un ajuste sin marcas.</li><li><strong>Cobertura Completa:</strong> Diseño que ofrece un ajuste cómodo y favorecedor.</li></ul><br/><p style='text-align:center'><strong>Cuidados de la prenda:</strong></p><ul><li>- Lavar a mano con agua fría para mantener la calidad.</li><li>- Evitar blanqueador, remojo y lavado en seco.</li><li>- Secar colgado y a la sombra, sin retorcer ni usar secadora.</li></ul><br/><p style='text-align:center'><strong>Sugerencias adicionales:</strong></p><ul><li>1. Al lavar, usar detergente suave y evitar fricción.</li><li>2. Evitar superficies ásperas y almacenar en lugar fresco y seco.</li></ul></body>
A7: =VLOOKUP(B7,Sheet1!A:B,2,FALSE) -> 135 | B7: Conjunto pijama en algodón con short corto | C7: Sueños dulces para las pequeñas. Esta pijama para niñas, elaborada en algodón, cuenta con dos piezas: una camiseta sin mangas con cuello redondo y un short corto con un suave elástico que se ciñe en la cintura. Ideal para vestir todas las noches.<br><br><strong>Características Destacadas:</strong><br><strong>Algodón natural:</strong> Suavidad y frescura para la piel delicada de las niñas.<br><strong>Camiseta sin mangas:</strong> Ideal para noches cálidas.<br><strong>Short con elástico suave:</strong> Ajuste cómodo y seguro. | D7: Algodón natural: Suavidad y frescura para la piel delicada de las niñas Camiseta sin mangas: Ideal para noches cálidas Short con elástico suave: Ajuste cómodo y seguro | E7: <body><h2>Conjunto pijama en algodón con short corto</h2><br/><p>Sueños dulces para las pequeñas. Esta pijama para niñas, elaborada en algodón, cuenta con dos piezas: una camiseta sin mangas con cuello redondo y un short corto con un suave elástico que se ciñe en la cintura. Ideal para vestir todas las noches.</p><br/><strong>Características Destacadas:</strong><br><ul><li>Algodón natural: Suavidad y frescura para la piel delicada de las niñas.</li><li>Camiseta sin mangas: Ideal para noches cálidas.</li><li>Short con elástico suave: Ajuste cómodo y seguro.</li></ul>
A8: =VLOOKUP(B8,Sheet1!A:B,2,FALSE) -> 136 | B8: Panty paquete x5 hípster microfibra | C8: Paquete de 5 pantys tipo hípster, diseñados para ofrecer comodidad y suavidad en cada uso. Conocida por su comodidad y agradable tacto, la tecnología de Termofusionado se ajusta suavemente al cuerpo en la cadera. Evita que se enrolle y previene marcas visibles, ideal para prendas ajustadas. Favorece la figura y proporciona un ajuste cómodo. Asegura higiene y frescura en la zona íntima, ofreciendo versatilidad y funcionalidad para el día a día. Lavar a mano o en lavadora en ciclo delicado, evitar agua caliente, blanqueador, remojo y lavado en seco, secar colgado y a la sombra, sin planchar ni usar secadora. | D8: Silueta ajustada que realza las curvas Tecnología de Termofusionado para ajuste suave en la cadera Corte Láser evita enrolamiento y marcas visibles | E8: <body><h2>Panty paquete x5 hípster microfibra</h2><br/><p>Descubre nuestro paquete de 5 panties tipo hípster, diseñados para ofrecer comodidad y suavidad en cada uso.<br>_x000D_ <strong>Características destacadas:</strong><br>_x000D_ <strong>Microfibra Suave:</strong> Conocida por su comodidad y agradable tacto.<br>_x000D_ <strong>Tecnología de Termofusionado:</strong> Se ajusta suavemente al cuerpo en la cadera.<br>_x000D_ <strong>Corte Láser en las Piernas:</strong> Evita que se enrolle y previene marcas visibles, ideal para prendas ajustadas.<br>_x000D_ <strong>Talle Medio:</strong> Favorece la figura y proporciona un ajuste cómodo.<br>_x000D_ <strong>Refuerzo de Algodón:</strong> Asegura higiene y frescura en la zona íntima, ofreciendo versatilidad y funcionalidad para el día a día.<br>_x000D_ <br><strong>Cuidados de la prenda:</strong><br>_x000D_ - Lavar a mano o en lavadora en ciclo delicado.<br>_x000D_ - Evitar agua caliente, blanqueador, remojo y lavado en seco.<br>_x000D_ - Secar colgado y a la sombra, sin planchar ni usar secadora.<br>_x000D_ <strong>Sugerencias adicionales:</strong><br>_x000D_ 1. Al lavar, usar detergente suave y evitar fricción.<br>_x000D_ 2. Evitar superficies ásperas y almacenar en lugar fresco y seco.</p><br/><p><strong>Destacado</strong></p><ul><li><strong>Silueta ajustada:</strong> Realza las curvas.</li><li><strong>Tecnología de Termofusionado:</strong> Se ajusta suavemente al cuerpo en la cadera.</li><li><strong>Corte Láser evita enrolamiento y marcas visibles:</strong> Ideal para prendas ajustadas.</li></ul></body>
A9: =VLOOKUP(B9,Sheet1!A:B,2,FALSE) -> 137 | B9: Copas de silicona con extensión superior | C9: Copas de silicona con extensión superior para un apoyo natural. Ideal para usar bajo prendas de hombros y espalda descubiertas. Lávate las manos, lava con agua fría o tibia, no uses blanqueador ni seca, sécalas horizontalmente a la sombra, no retuercas, más sugerencias... | D9: Silicón ajustable para un apoyo natural Extensión superior para el hombro y espalda descubierta Se adecúa con prendas de hombros y/o espalda | E9: <body><h2>Copas de silicona con extensión superior</h2><p>Descripción mejorada con IA. Ideal para usar bajo prendas de hombros y espalda descubiertas. Lávate las manos, lava con agua fría o tibia, no uses blanqueador ni seca, sécalas horizontalmente a la sombra, no retuercas, más sugerencias...</p><ul><li>Ajuste de silicona para un apoyo natural</li><li>Extensión superior: Ideal para hombro y espalda descubiertas</li><li>Compatibilidad con prendas de hombros y/o espalda</li></ul></body>
A10: =VLOOKUP(B10,Sheet1!A:B,2,FALSE) -> 138 | B10: Brasier materno sin costuras tipo seamless | C10: Práctico y adaptable para la lactancia, este brasier materno se ajusta al cuerpo mediante tecnología seamless, proporcionando flexibilidad y soporte donde más lo necesitas. Sus copas removibles y el broche frontal lo convierten en una opción ideal para las mamás en etapa de lactancia. | D10: Tecnología seamless: Diseño sin costuras laterales que no marca ni incomoda Copas removibles: Ajuste personalizado para mayor soporte Soporte adicional: Refuerzo en las copas que garantiza seguridad al abrir el broche Broche ancho: Comodidad y estabilidad para todo el día | E10: <body><h2><strong style='font-size:24px'>Brasier materno sin costuras tipo seamless</strong></h2><br/><p style='text-align:justify'><span style='font-size:18px'>Práctico y adaptable para la lactancia, este brasier materno se ajusta al cuerpo mediante tecnología seamless, proporcionando flexibilidad y soporte donde más lo necesitas. Sus copas removibles y el broche frontal lo convierten en una opción ideal para las mamás en etapa de lactancia.</span></p><br/><ul><li style='font-size:18px'>Tecnología seamless: Diseño sin costuras laterales que no marca ni incomoda</li><li style='font-size:18px'>Copas removibles: Ajuste personalizado para mayor soporte</li><li style='font-size:18px'>Soporte adicional: Refuerzo en las copas que garantiza seguridad al abrir el broche</li></ul></body>
A11: =VLOOKUP(B11,Sheet1!A:B,2,FALSE) -> 139 | B11: Top con copas individual corte láse teen | C11: ¡Una prenda ligera como el aire! Este top para teens, con tecnología de corte láser y termofusionado, se siente como una segunda piel. Su textura acanalada y copas removibles garantizan comodidad y versatilidad, mientras que sus cargaderas anchas cuidan tus hombros. | D11: Tecnología de corte láser: Acabados invisibles y delicados. Copas removibles: Se adapta a tus preferencias. Cargaderas anchas: Soporte cómodo sin lastimar. | E11: <body><h2>Top con copas individual corte láse teen</h2><br/><p>Seda ligera como el aire. Tecnología de corte láser y termofusionado para comodidad.</p><ul><li>Tecnología de corte láser: Acabados invisibles y delicados.</li><li>Copas removibles: Se adapta a tus preferencias.</li><li>Cargaderas anchas: Soporte cómodo sin lastimar.</li></ul></body>
A12: =VLOOKUP(B12,Sheet1!A:B,2,FALSE) -> 142 | B12: Paquete x2 bóxer en algodón para niña | C12: <p>Disfruta de la comodidad con nuestro panty bóxer de algodón. Flexible y fresco, con detalles en tonos contrastantes para un toque de estilo y excelente cobertura.</p>_x000D_ _x000D_ <p><strong>Características Destacadas:</strong></p>_x000D_ <ul><li><strong>Algodón flexible:</strong> Brinda frescura y confort.</li><li><strong>Detalles en tonos contrastantes:</strong> Toque de estilo.</li><li><strong>Excelente cobertura:</strong> Ajuste cómodo durante todo el día.</li></ul> | D12: Silueta ajustada que realza las curvas Escote cruzado en el frente con canal Cargaderas ajustables para mejor ajuste | E12: <body><h2>Paquete x2 bóxer en algodón para niña</h2><br/><p style='text-align:justify'><span style='font-size:18px'>Disfruta de la comodidad con nuestro panty bóxer de algodón. Flexible y fresco, con detalles en tonos contrastantes para un toque de estilo y excelente cobertura.</span></p><br/><p><strong>Características Destacadas:</strong></p><ul><li style='font-size:16px'><span style='font-size:18px'>Algodón flexible:</span> Brinda frescura y confort.</li><li style='font-size:16px'><span style='font-size:18px'>Detalles en tonos contrastantes:</span> Toque de estilo.</li><li style='font-size:16px'><span style='font-size:18px'>Excelente cobertura:</span> Ajuste cómodo durante todo el día.</li></ul></body>
A13: =VLOOKUP(B13,Sheet1!A:B,2,FALSE) -> 140 | B13: Brasier copa "c" línea plus size | C13: Mejorarlo tomando en cuenta la data suministrada<br><br><strong>Características:</strong><br><strong>Material:</strong> Microfibra.<br><strong>Diseño:</strong> Copa "C" de cobertura media.<br><strong>Cuidados de la prenda:</strong><br>_x000D_ - Lavar a mano con agua fría para mantener la calidad.<br>_x000D_ - Evitar blanqueador, remojo y lavado en seco.<br>_x000D_ - Secar colgado y a la sombra, sin retorcer ni usar secadora.<br>_x000D_ <strong>Sugerencias adicionales:</strong><br>_x000D_ 1. Al lavar, usar detergente suave y evitar fricción.<br>_x000D_ 2. Evitar superficies ásperas y almacenar en lugar fresco y seco. | D13: Silueta ajustada que realza las curvas Escote cruzado en el frente con canal Cargaderas ajustables para mejor ajuste | E13: <body><h2>Brasier copa "c" línea plus size</h2><br/><p>Mejorarlo tomando en cuenta la data suministrada<br><br><strong>Características:</strong><br><strong>Material:</strong> Microfibra.<br><strong>Diseño:</strong> Copa "C" de cobertura media.<br><strong>Cuidados de la prenda:</strong><br>_x000D_ - Lavar a mano con agua fría para mantener la calidad.<br>_x000D_ - Evitar blanqueador, remojo y lavado en seco.<br>_x000D_ - Secar colgado y a la sombra, sin retorcer ni usar secadora.<br>_x000D_ <strong>Sugerencias adicionales:</strong><br>_x000D_ 1. Al lavar, usar detergente suave y evitar fricción.<br>_x000D_ 2. Evitar superficies ásperas y almacenar en lugar fresco y seco.</p></body>
... A317: =VLOOKUP(B317,Sheet1!A:B,2,FALSE) -> 448 | B317: Panty paq x3 tipo hipster invisible | C317: Mejorarlo tomando en cuenta la data suministrada<br>_x000D_ Pack X3 de panties con silueta tipo hipster, elaborados en microfibra, un material suave que garantiza comodidad durante todo el día. Diseñados con tecnología de corte a ras en las piernas y un delicado sesgo que se ajusta suavemente en la cintura, estos panties ofrecen un acabado limpio e invisible bajo las prendas ajustadas. Además, incluyen un refuerzo en algodón que asegura frescura e higiene en la zona íntima, convirtiéndolos en una opción perfecta para el día a día.<br_x000D_ Cuidados de la prenda:</r >_x000D_ - Lavar a mano o en lavadora en ciclo delicado._x000D_ >_x000D_ - Evitar agua caliente, blanqueador, remojo y lavado en seco._x000D_ >_x000D_ - Secar colgado y a la sombra, sin planchar ni usar secadora._x000D_ _x000D_ Sugerencias adicionales:_x000D_ >_x000D_ 1. Al lavar, usar detergente suave y evitar fricción._x000D_ >_x000D_ 2. Evitar superficies ásperas y almacenar en lugar fresco y seco. | D317: Silueta ajustada que realza las curvas Escote cruzado en el frente con canal Cargaderas ajustables para mejor ajuste | E317: <body><h2><strong style='font-size:24px'>Panty paq x3 tipo hipster invisible</strong></h2><br/><p style='text-align:justify'><span style='font-size:18px'>Mejorarlo tomando en cuenta la data suministrada</span><strong style='font-size:18px'>Pack X3 de panties con silueta tipo hipster, elaborados en microfibra, un material suave que garantiza comodidad durante todo el día. Diseñados con tecnología de corte a ras en las piernas y un delicado sesgo que se ajusta suavemente en la cintura, estos panties ofrecen un acabado limpio e invisible bajo las prendas ajustadas. Además, incluyen un refuerzo en algodón que asegura frescura e higiene en la zona íntima, convirtiéndolos en una opción perfecta para el día a día.</strong></p><br/><p style='text-align:center'><strong>Características destacadas</strong></p><ul><li><strong>Silueta ajustada:</strong> Realza las curvas.</li><li><strong>Escote cruzado:</strong> Agrega sofisticación.</li><li><strong>Cargaderas ajustables:</strong> Para mayor comodidad.</li></ul></body>
A318: =VLOOKUP(B318,Sheet1!A:B,2,FALSE) -> 449 | B318: Paquete x5 panty brasilera de encaje | C318: <p><strong>Diseñados pensando en cada detalle, nuestros panties tipo brasilera en encaje X5 combinan feminidad y comodidad. Su delicado diseño de encaje realza tu estilo, mientras que el refuerzo en algodón asegura higiene y frescura durante todo el día.</strong><br><br><strong>Características:</strong></p><ul><li>Diseño: Estilo brasilera con encaje delicado para un toque femenino.</li><li>Material: Encaje suave y cómodo que se adapta a tu cuerpo.</li><li>Refuerzo: Algodón en la zona íntima para mayor higiene.</li><li>Talle: Medio, ideal para el uso diario.</li><li>Paquetería: Cinco piezas versátiles y elegantes.</li></ul><p><strong>Cuidados de la prenda:</strong></p><ol><li>Lavar a mano suavemente con agua fría.</li><li>Evitar blanqueador, remojo y lavado en seco.</li><li>Secar horizontal y a la sombra, sin planchar ni usar secadora.</li><li>Sugerencias adicionales:</li></ol><ul><li>Al lavar, usar detergente suave y evitar fricción.</li><li>Evitar superficies ásperas y almacenar en lugar fresco y seco.</li></ul> | D318: Diseño brasilera con encaje delicado Material suave y cómodo que se adapta al cuerpo Refuerzo de algodón para higiene
A319: =VLOOKUP(B319,Sheet1!A:B,2,FALSE) -> 450 | B319: Top para adolecentes tipo seamless paq x2 | C319: ¡Regresa a la escuela con un estilo impresionante! Nuestro Top para adolescentes tiene ganchos en la espalda y viene en un embalaje fácil de paquetería X2. Diseñado específicamente para el segmento Junior, este top seamless sin costuras se ajusta perfectamente a tu cuerpo con una suave y transpirable poliamida. Los tirantes ajustables y base delgada de este top proporcionan ligereza, comodidad y movimiento fluido, asegurándote un look impecable para cada día escolar.<br>¡Cuidado y almacenamiento adecuados mantienen tu top en su mejor forma! | D319: Silueta ajustada que realza las curvas Escote cruzado en el frente con canal Tirantes y base delgada para comodidad | E319: <body><h2>Top para adolecentes tipo seamless paq x2</h2><br/><p style='text-align:justify'>¡Vuelve a la escuela con un estilo impecable! Nuestro Top para adolescentes con ganchos en la espalda viene embalado fácilmente en una paquetería X2. Diseñado específicamente para los niños del segmento Junior, este top seamless sin costuras se ajusta perfectamente a tu cuerpo y está hecho de poliamida suave y transpirable. Los tirantes ajustables y base delgada de este top proporcionan ligereza, comodidad y movimiento fluido, asegurándote un look impresionante para cada día escolar.<br>¡Cuide y almacene adecuadamente a tu top para mantenerla en su mejor forma!</p><br/><strong>Sugerencias:</strong></body>
A320: =VLOOKUP(B320,Sheet1!A:B,2,FALSE) -> 451 | B320: Brasilera en algodón con encaje paquete x3 | C320: Mejorarlo tomando en cuenta la data suministrada<br><br>Detalles de encaje en piernas y cintura.<br>Máxima Comodidad:<br>Refuerzo en algodón para mayor confort y absorción.<br>Diseño sensual:<br>Talle bajo y costados angostos.<br>Cuidados de la prenda:<br>- Lavar a mano o en lavadora en ciclo delicado.<br>- Evitar agua caliente, blanqueador, remojo y lavado en seco.<br>- Secar colgado y a la sombra, sin planchar ni usar secadora.<br>Sugerencias adicionales:<br>1. Al lavar, usar detergente suave y evitar fricción.<br>2. Evitar superficies ásperas y almacenar en lugar fresco y seco. | D320: Detalles de encaje en piernas y cintura Refuerzo en algodón para mayor comodidad Talle bajo y costados angostos | E320: <body><h2>Brasilera en algodón con encaje paquete x3</h2><br/><p style='text-align:justify'><span style='font-size:18px'>Descripción mejorada con IA</span><strong style='font-size:18px'>¡Llamado a la acción, ejemplo: Elige tu color y destaca!</strong></p><br/><p><strong>Destacado</strong></p><ul><li>Detalles de encaje en piernas y cintura</li><li>Refuerzo en algodón para mayor comodidad</li><li>Talle bajo y costados angostos</li></ul></body>
A321: =VLOOKUP(B321,Sheet1!A:B,2,FALSE) -> 452 | B321: Brasier en poliamida para adolecentes paquete x2 | C321: Paquete de brasería sin aros para adolescentes, confeccionado en resistente y elastico poliamida que se adapta suavemente al cuerpo. Diseño seamless elimina costuras invisibles bajo la ropa, silueta strapless ideal para prendas sin mangas o escotes. | D321: Material resistente y elasticidad alta Seamless tecnologia evita costuras Silueta strapless ideal para prendas sin mangas | E321: <body><h2>Brasier en poliamida paquete x2</h2><br/><p>Cuadro resistente y elastico, adapta suavemente al cuerpo. Diseño seamless elimina costuras invisibles.</p><ul><li>Materiales resistentes y elásticos</li><li>Tecnología seamless evita costuras</li><li>Silueta strapless ideal para prendas sin mangas</li></ul></body>
A322: =VLOOKUP(B322,Sheet1!A:B,2,FALSE) -> 453 | B322: Top para niña con tecnología sin costuras paquete x2 | C322: Nuestro top para niña en poliamida con tecnología seamless ofrece un ajuste cómodo y sin costuras, ideal para actividades físicas o uso diario. La espalda deportiva brinda libertad de movimiento, mientras que los tirantes anchos proporcionan soporte adicional.<br><br>_x000D_ _x000D_ <strong>Características destacadas</strong><br>_x000D_ <strong>Poliamida sin costuras:</strong> Confort óptimo.<br>_x000D_ <strong>Espalda deportiva:</strong> Mayor libertad de movimiento.<br>_x000D_ <strong>Tirantes anchos:</strong> Soporte adicional.<br>_x000D_ <strong>Diseño versátil:</strong> Ideal para actividades o uso diario.<br><br><br<strong>Cuidados de la prenda:</strong><br>_x000D_ - Lavar a mano suavemente con agua fría.<br>_x000D_ - Evitar blanqueador, remojo y lavado en seco.<br>_x000D_ - Secar horizontal y a la sombra, sin planchar ni usar secadora.<br>_x000D_ <strong>Sugerencias adicionales:</strong><br>_x000D_ 1. Almacenar en lugar fresco y seco, lejos de luz solar y objetos ásperos.<br>_x000D_ 2. Evitar cremas o lociones que puedan manchar. | D322: Poliamida sin costuras: Confort óptimo Espalda deportiva: Mayor libertad de movimiento Tirantes anchos: Soporte adicional | E322: <body><h2>Top para niña con tecnología sin costuras paquete x2</h2><br/><p style='text-align:justify'><span style='font-size:18px'>Nuestro top para niña en poliamida con tecnología seamless ofrece un ajuste cómodo y sin costuras, ideal para actividades físicas o uso diario. La espalda deportiva brinda libertad de movimiento, mientras que los tirantes anchos proporcionan soporte adicional.</span><br/><strong>Características destacadas</strong><br/>Poliamida sin costuras: Confort óptimo<br/>Espalda deportiva: Mayor libertad de movimiento<br/>Tirantes anchos: Soporte adicional<br/>Diseño versátil: Ideal para actividades o uso diario<br/><br/><strong>Cuidados de la prenda:</strong><br/>- Lavar a mano suavemente con agua fría.<br/>- Evitar blanqueador, remojo y lavado en seco.<br/>- Secar horizontal y a la sombra, sin planchar ni usar secadora.<br/><br/><strong>Sugerencias adicionales:</strong><br/>1. Almacenar en lugar fresco y seco, lejos de luz solar y objetos ásperos.<br/>2. Evitar cremas o lociones que puedan manchar.</p></body>
A323: =VLOOKUP(B323,Sheet1!A:B,2,FALSE) -> 454 | B323: Conjunto pijama con camiseta con manga corta | C323: Este conjunto de pijamas, elaborado en material suave con textura acanalada, incluye una camisa holgada con cuello amplio redondo y un pantalón corto con lazo ajustable. Ideal para noches relajadas. | D323: Camisa holgada: Diseño fresco y relajado con manga corta Pantalón corto: Lazo en la cintura para un ajuste ideal Textura acanalada: Detalle moderno y atemporal | E323: <body><h2>Conjunto pijama con camiseta con manga corta</h2><p>Este conjunto de pijamas, elaborado en material suave con textura acanalada, incluye una camisa holgada con cuello amplio redondo y un pantalón corto con lazo ajustable. Ideal para noches relajadas.</p><br/><h3>Características</h3><ul><li>Camisa holgada: Diseño fresco y relajado con manga corta</li><li>Pantalón corto: Lazo en la cintura para un ajuste ideal</li><li>Textura acanalada: Detalle moderno y atemporal</li></ul></body>
A324: =VLOOKUP(B324,Sheet1!A:B,2,FALSE) -> 455 | B324: Panty hipster x3 unidades en encaje | C324: Conoce nuestro panty tipo hipster en paquete de 3 unidades, diseñado para ofrecer cobertura media en las piernas y los glúteos. Elaborado en malla con un patrón floral, este panty combina frescura y un toque de feminidad. Su diseño incluye un delicado corte en la parte posterior que añade un detalle sensual y sutil. Además, cuenta con un refuerzo en algodón que garantiza transpirabilidad e higiene en la zona íntima, ideal para el día a día.<br> Cuidados de la prenda: Lavar a mano suavemente con agua fría. Evitar blanqueador, remojo y lavado en seco. Secar horizontal y a la sombra, sin planchar ni usar secadora. Sugerencias adicionales: 1. Al lavar, usar detergente suave y evitar fricción. 2. Evitar superficies ásperas y almacenar en lugar fresco y seco. | D324: Panty hipster para cobertura media Paquete de 3 unidades en encaje floral Malla suave con refuerzo en algodón | E324: <body><h2>Panty hipster x3 unidades en encaje</h2><br/><p>Conoce nuestro panty tipo hipster en paquete de 3 unidades, diseñado para ofrecer cobertura media en las piernas y los glúteos. Elaborado en malla con un patrón floral, este panty combina frescura y un toque de feminidad. Su diseño incluye un delicado corte en la parte posterior que añade un detalle sensual y sutil. Además, cuenta con un refuerzo en algodón que garantiza transpirabilidad e higiene en la zona íntima, ideal para el día a día.<br> Cuidados de la prenda: Lavar a mano suavemente con agua fría. Evitar blanqueador, remojo y lavado en seco. Secar horizontal y a la sombra, sin planchar ni usar secadora. Sugerencias adicionales: 1. Al lavar, usar detergente suave y evitar fricción. 2. Evitar superficies ásperas y almacenar en lugar fresco y seco.</p><br/><ul><li>Panty hipster para cobertura media</li><li>Paquete de 3 unidades en encaje floral</li><li>Malla suave con refuerzo en algodón</li></ul></body>
A325: =VLOOKUP(B325,Sheet1!A:B,2,FALSE) -> 456 | B325: Brasier strapless de algodón x2 und | C325: Siente la libertad y soporte con nuestro brasier strapless en algodón, diseñado con copa "B" y un realce medio que puede aumentar hasta una talla. La base delicada debajo de la copa ofrece un soporte adicional, mientras que los tirantes multiusos y ajustables permiten un ajuste personalizado y cómodo para todo el día.<br><br>_x000D_ _x000D_ <strong>Características destacadas</strong><br><strong>Algodón flexible:</strong> Confort óptimo.<br><strong>Copa "B" strapless:</strong> Realce medio y soporte.<br><strong>Base bajo la copa:</strong> Refuerzo adicional.<br><strong>Tirantes multiusos y ajustables:</strong> Versatilidad en el ajuste.<br><br><br<strong>Cuidados de la prenda:</strong><br>_x000D_ - Lavar a mano con agua fría para mantener la calidad y forma.<br>_x000D_ - No usar blanqueador ni dejar en remojo.<br>_x000D_ - Secar colgado y a la sombra, sin retorcer ni usar secadora.<br>_x000D_ <strong>Sugerencias adicionales:</strong><br>_x000D_ 1. Al lavar, usar detergente suave y evitar fricción.<br>_x000D_ 2. Evitar superficies ásperas y almacenar en lugar fresco y seco. | D325: Silueta ajustada que realza las curvas Escote cruzado en el frente con canal Cargaderas ajustables para mejor ajuste | E325: <body><h2><strong style='font-size:24px'>Brasier strapless de algodón x2 und</strong></h2><br/><p style='text-align:justify'><span style='font-size:18px'>Siente la libertad y soporte con nuestro brasier strapless en algodón, diseñado con copa "B" y un realce medio que puede aumentar hasta una talla. La base delicada debajo de la copa ofrece un soporte adicional, mientras que los tirantes multiusos y ajustables permiten un ajuste personalizado y cómodo para todo el día.</span><strong style='font-size:18px'>¡Llamado a la acción, ejemplo: Elige tu color y destaca!</strong></p><br/><p><strong>Destacado</strong></p><ul><li><strong>Silueta ajustada:</strong> Realza las curvas.</li><li><strong>Escote cruzado:</strong> Agrega sofisticación.</li><li><strong>Cargaderas ajustables:</strong> Para mayor comodidad.</li></ul></body>
A326: =VLOOKUP(B326,Sheet1!A:B,2,FALSE) -> 457 | B326: Panty hipster corte laser en microfibra x5 | C326: Mejorarlo tomando en cuenta la data suministrada | D326: Silueta ajustada que realza las curvas Escote cruzado en el frente con canal Cargaderas ajustables para mejor ajuste | E326: <body><h2><strong style='font-size:24px'>Panty hipster corte laser en microfibra x5</strong></h2><br/><p style='text-align:justify'><span style='font-size:18px'>Descripción mejorada con IA</span><strong style='font-size:18px'>¡Llamado a la acción, ejemplo: Elige tu color y destaca!</strong></p><br/><p><strong>Destacado</strong></p><ul><li><strong>Silueta ajustada:</strong> Realza las curvas.</li><li><strong>Escote cruzado:</strong> Agrega sofisticación.</li><li><strong>Cargaderas ajustables:</strong> Para mayor comodidad.</li></ul></body>
A327: =VLOOKUP(B327,Sheet1!A:B,2,FALSE) -> 458 | B327: Top con copas seamless y tiras ajustables x2 unidades | C327: Descubre la fusión perfecta de comodidad y estilo con nuestro top en poliamida Seamless! Este top en paquetería X2 está diseñado con tecnología Seamless, lo que significa que no tiene costuras en el contorno, ofreciendo un ajuste impecable que se adapta a tu cuerpo de manera natural. Su textura acanalada añade un detalle innovador, mientras que los tirantes ajustables y la base delgada garantizan una sensación de ligereza y libertad. Además, el logo en la base aporta un toque delicado y en tendencia. Ideal para quienes buscan confort sin sacrificar estilo. | D327: Silueta ajustada que realza las curvas Escote cruzado en el frente con canal Cargaderas ajustables para mejor ajuste | E327: <body><h2>Top con copas seamless y tiras ajustables x2 unidades</h2><br/><p style='text-align:justify'><span>Descubre la fusión perfecta de comodidad y estilo con nuestro top en poliamida Seamless! Este top en paquetería X2 está diseñado con tecnología Seamless, lo que significa que no tiene costuras en el contorno, ofreciendo un ajuste impecable que se adapta a tu cuerpo de manera natural. Su textura acanalada añade un detalle innovador, mientras que los tirantes ajustables y la base delgada garantizan una sensación de ligereza y libertad. Además, el logo en la base aporta un toque delicado y en tendencia. Ideal para quienes buscan confort sin sacrificar estilo.</span></p><br/><p style='text-align:center'><strong>Destacado</strong></p><ul><li>Silueta ajustada: Realza las curvas</li><li>Escote cruzado: Agrega sofisticación</li><li>Cargaderas ajustables: Para mayor comodidad</li></ul></body>
A328: =VLOOKUP(B328,Sheet1!A:B,2,FALSE) -> 459 | B328: Panty paq x3 hipster tipo seamless | C328: ¡NUEVA TEXTURA! Pack X2 de panties del segmento Kids Girl, con silueta tipo hipster y cobertura media en los glúteos y las piernas. Elaborados en poliamida, un material de alta elasticidad que ofrece comodidad y un ajuste suave sobre la piel. Su textura tipo espiga añade un detalle innovador y moderno. Diseñados con tecnología sin costuras en los costados, evitan marcas visibles, permitiendo moverse con total libertad. Incluyen un refuerzo en algodón que asegura higiene y frescura en la zona íntima, convirtiéndolos en la opción ideal para el uso diario.<brstrong>Cuidados de la prenda:</strong><br_x000D_ - Lavar a mano o en lavadora en ciclo delicado.<br_x000D_ - Evitar agua caliente, blanqueador, remojo y lavado en seco.<br_x000D_ - Secar colgado y a la sombra, sin planchar ni usar secadora.<br_x000D_ <strong>Sugerencias adicionales:</strong><br_x000D_ 1. Al lavar, usar detergente suave y evitar fricción.<br_x000D_ 2. Evitar superficies ásperas y almacenar en lugar fresco y seco. | D328: Silueta ajustada que realza las curvas Escote cruzado en el frente con canal Cargaderas ajustables para mejor ajuste | E328: <body><h2><strong style='font-size:24px'>Panty paq x3 hipster tipo seamless</strong></h2><br/><p style='text-align:justify'><span style='font-size:18px'>¡NUEVA TEXTURA! Pack X2 de panties del segmento Kids Girl, con silueta tipo hipster y cobertura media en los glúteos y las piernas. Elaborados en poliamida, un material de alta elasticidad que ofrece comodidad y un ajuste suave sobre la piel. Su textura tipo espiga añade un detalle innovador y moderno.</span><strong style='font-size:18px'>Diseñados con tecnología sin costuras en los costados, evitan marcas visibles, permitiendo moverse con total libertad. Incluyen un refuerzo en algodón que asegura higiene y frescura en la zona íntima, convirtiéndolos en la opción ideal para el uso diario.</strong></p><br/><p><strong>Cuidados de la prenda:</strong></p><ul><li><strong>Lavar a mano o en lavadora en ciclo delicado.</strong></li><li><strong>Evitar agua caliente, blanqueador, remojo y lavado en seco.</strong></li><li><strong>Secar colgado y a la sombra, sin planchar ni usar secadora.</strong></li></ul><br/><p><strong>Sugerencias adicionales:</strong></p><ul><li><strong>Al lavar, usar detergente suave y evitar fricción.</strong></li><li><strong>Evitar superficies ásperas y almacenar en lugar fresco y seco.</strong></li></ul></body>
A329: =VLOOKUP(B329,Sheet1!A:B,2,FALSE) -> 460 | B329: Top paq x2 tipo seamless para adolecentes | C329: Prepárate para el regreso a clases con nuestro Top en Paquetería X2, diseñado especialmente para el segmento Junior. Confeccionado en una suave y transpirable poliamida, este top seamless sin costuras garantiza un ajuste impecable que se adapta a tu cuerpo. Los tirantes ajustables y la base delgada ofrecen ligereza y libertad, mientras que el detalle fruncido en el centro mejora el ajuste en el busto. Con copas removibles para personalizar tu look, es la prenda perfecta para acompañarte con comodidad y estilo en tu rutina escolar. | D329: Silueta ajustada que realza las curvas Escote cruzado en el frente con canal Cargaderas ajustables para mejor ajuste | E329: <body><h2>Top paq x2 tipo seamless para adolecentes</h2><br/><p style='text-align:justify'>¡Back to School! Prepárate para el regreso a clases con nuestro Top en Paquetería X2, diseñado especialmente para el segmento Junior. Confeccionado en una suave y transpirable poliamida, este top seamless sin costuras garantiza un ajuste impecable que se adapta a tu cuerpo.</p><br/><ul><li>Silueta ajustada: Realza las curvas</li><li>Escote cruzado: Agrega sofisticación</li><li>Cargaderas ajustables: Para mayor comodidad</li></ul></body>
A330: =VLOOKUP(B330,Sheet1!A:B,2,FALSE) -> 461 | B330: Vestido de baño enterizo de microfibra | C330: Sumerge en el agua con este vestido de baño entero, confeccionado en microfibra suave y confortable, ideal para disfrutar del agua con estilo. Su delicada textura innovadora añade un detalle en tendencia. Cuenta con tirantes amplios que garantizan un ajuste personalizado y soporte excepcional al busto, mientras que las copas fijas con aros ofrecen seguridad y realce. La parte inferior, con una silueta tipo bikini, favorece tu figura, y el sutil escote redondo en la espalda añade un toque de sensualidad, convirtiendo esta prenda en la elección perfecta para brillar bajo el sol. | D330: Silueta ajustada que realza las curvas Escote cruzado en el frente con canal Cargaderas amplias y soportes excepcionales | E330: <body><h2>Vestido de baño entizo de microfibra</h2><br/><p>Sumerge en el agua con este vestido de baño entero, confeccionado en microfibra suave y confortable, ideal para disfrutar del agua con estilo. Su delicada textura innovadora añade un detalle en tendencia.</p><ul><li>Silueta ajustada: Realza las curvas</li><li>Escote cruzado: Agrega sofisticación</li><li>Cargaderas amplias y soportes excepcionales: Para mayor comodidad</li></ul><br/><p>Cuenta con tirantes amplios que garantizan un ajuste personalizado y soporte excepcional al busto, mientras que las copas fijas con aros ofrecen seguridad y realce.</p><br/>La parte inferior, con una silueta tipo bikini, favorece tu figura, y el sutil escote redondo en la espalda añade un toque de sensualidad, convirtiendo esta prenda en la elección perfecta para brillar bajo el sol.</p></body>
... A355: =VLOOKUP(B355,Sheet1!A:B,2,FALSE) -> 486 | B355: Panty hipster invisible en microfibra paquete x5 | C355: Mejorarlo tomando en cuenta la data suministrada | D355: Silueta ajustada que realza las curvas Escote cruzado en el frente con canal Cargaderas ajustables para mejor ajuste | E355: <body><h2>Panty hipster invisible en microfibra paquete x5</h2><br/><p>Descripción mejorada con IA</p><ul><li>Silueta ajustada: Realza las curvas.</li><li>Escote cruzado: Agrega sofisticación.</li><li>Cargaderas ajustables: Para mayor comodidad.</li></ul></body>
A356: =VLOOKUP(B356,Sheet1!A:B,2,FALSE) -> 487 | B356: Panty tipo brasilera invisible microfibra paquete x5 | D356: Silueta ajustada para realzar las curvas del cuerpo. Escote cruzado en el frente con canal para mayor comodidad y sofisticación. Cargaderas ajustables para un mejor ajuste a la cintura. | E356: <body><h2>Panty tipo brasilera invisible microfibra paquete x5</h2><br/><p>Descripción mejorada con IA<br/>¡Llamado a la acción, ejemplo: Elige tu color y destaca!</p><br/><p><strong>Destacado</strong></p><ul><li><strong>Silueta ajustada:</strong> Realza las curvas.</li><li><strong>Escote cruzado:</strong> Agrega sofisticación.</li><li><strong>Cargaderas ajustables:</strong> Para mayor comodidad.</li></ul></body>
A357: =VLOOKUP(B357,Sheet1!A:B,2,FALSE) -> 488 | B357: Hipster invisible en microfibra paquete x5 | C357: <p>Cuidados de la prenda:<br>- Lavar a mano o en lavadora en ciclo delicado.<br>- Evitar agua caliente, blanqueador, remojo y lavado en seco.<br>- Secar colgado y a la sombra, sin planchar ni usar secadora.<br>Sugerencias adicionales:<br>1. Al lavar, usar detergente suave y evitar fricción.<br>2. Evitar superficies ásperas y almacenar en lugar fresco y seco.</p> | D357: Silueta ajustada que realza las curvas Escote cruzado en el frente con canal Cargaderas ajustables para mejor ajuste | E357: <body><h2>Hipster invisible en microfibra paquete x5</h2><br/><p>Este modelo invisible está hecho de microfibra suave y proporciona una apariencia deslumbrante sin sacrificar la comodidad. Está disponible en paquetes de 5 para mayor conveniencia.</p><br/><ul><li>Silueta ajustada: Realza las curvas para darle a tus formas un toque elegante y sensual.</li><li>Escote cruzado: Añade una apariencia sofisticada al frente con canal.</li><li>Cargaderas ajustables: Para mayor comodidad, el cinturón ajustable asegura un encaje perfecto.</li></ul></body>
A358: =VLOOKUP(B358,Sheet1!A:B,2,FALSE) -> 489 | B358: Panty bóxer de algodón paquete x3 para niña | C358: Descubre la comodidad esencial con nuestro panty tipo bóxer X3. Fabricado en algodón transpirable, su diseño te brinda un ajuste seguro y una cobertura amplia que se adapta perfectamente a tu ritmo diario._x000D_ _x000D_ Características:_x000D_ _x000D_ Material: Algodón transpirable para frescura y confort._x000D_ Cintura: Elástico suave para un ajuste perfecto._x000D_ Talle: Medio, con cobertura ampliada en la parte trasera._x000D_ Cobertura extra: Extensión hacia las piernas para mayor comodidad._x000D_ Paquetería: Tres piezas ideales para el uso diario.<br<strong>Cuidados de la prenda:</strong><br>_x000D_ - Lavar a mano o en lavadora en ciclo delicado.<br>_x000D_ - Evitar agua caliente, blanqueador, remojo y lavado en seco.<br>_x000D_ - Secar colgado y a la sombra, sin planchar ni usar secadora.<br> _x000D_ <strong>Sugerencias adicionales:</strong><br>_x000D_ 1. Al lavar, usar detergente suave y evitar fricción.<br>_x000D_ 2. Evitar superficies ásperas y almacenar en lugar fresco y seco. | D358: Silueta ajustada que realza las curvas Escote cruzado en el frente con canal Cargaderas ajustables para mejor ajuste | E358: <body><h2>Panty bóxer de algodón paquete x3 para niña</h2><br/><p>Descubre la comodidad esencial con nuestro panty tipo bóxer X3. Fabricado en algodón transpirable, su diseño te brinda un ajuste seguro y una cobertura amplia que se adapta perfectamente a tu ritmo diario.</p><br/><ul><li>Material: Algodón transpirable para frescura y confort.</li><li>Cintura: Elástico suave para un ajuste perfecto.</li><li>Talle: Medio, con cobertura ampliada en la parte trasera.</li></ul><p><strong>Cuidados de la prenda:</strong></p><br/><p>- Lavar a mano o en lavadora en ciclo delicado.<br>- Evitar agua caliente, blanqueador, remojo y lavado en seco.<br>- Secar colgado y a la sombra, sin planchar ni usar secadora.</p><p><strong>Sugerencias adicionales:</strong></p><br/><ul><li>1. Al lavar, usar detergente suave y evitar fricción.</li><li>2. Evitar superficies ásperas y almacenar en lugar fresco y seco.</li></ul></body>
A359: =VLOOKUP(B359,Sheet1!A:B,2,FALSE) -> 490 | B359: Paqueteria x2 en camiseta de tiras para niña | C359: ¡Back to School! Prepárate para el regreso a clases con nuestro top largo en poliamida Seamless, diseñado para ofrecer la combinación perfecta de comodidad y estilo. Este top en Paquetería X2, confeccionado con tecnología sin costuras, se adapta naturalmente a tu cuerpo para un ajuste impecable. Su espalda atlética proporciona soporte suave y seguro, mientras que los tirantes delgados se ajustan suavemente a los hombros, garantizando mayor comodidad. Es la prenda ideal para quienes valoran practicidad y estilo en su rutina diaria. | D359: Silueta ajustada que realza las curvas Escote cruzado en el frente con canal Cargaderas ajustables para mejor ajuste | E359: <body><h2>Paqueteria x2 en camiseta de tiras para niña</h2><br/><p>¡Back to School! Prepárate para el regreso a clases con nuestro top largo en poliamida Seamless, diseñado para ofrecer la combinación perfecta de comodidad y estilo. Este top en Paquetería X2, confeccionado con tecnología sin costuras, se adapta naturalmente a tu cuerpo para un ajuste impecable. Su espalda atlética proporciona soporte suave y seguro, mientras que los tirantes delgados se ajustan suavemente a los hombros, garantizando mayor comodidad. Es la prenda ideal para quienes valoran practicabilidad y estilo en su rutina diaria.</p><br/><p>Cuidados de la prenda:</p><ul><li>Lavar a mano suavemente con agua fría.</li><li>Evitar blanqueador, remojo y lavado en seco.</li><li>Secar horizontal y a la sombra, sin planchar ni usar secadora.</li><li>Sugerencias adicionales:</li></ul><ol><li>Almacenar en lugar fresco y seco, lejos de luz solar y objetos ásperos.</li><li>Evitar cremas o lociones que puedan manchar.</li></ol></body>
A360: =VLOOKUP(B360,Sheet1!A:B,2,FALSE) -> 480 | B360: Brasier copa 3/4 x2 und en microfibra y encaje | C360: <p>Conoce nuestro conjunto de brasieres en paquetería x2, diseñados en estilo bustier para brindarte comodidad y un ajuste favorecedor. Las copas están elaboradas en microfibra para una sensación suave y cómoda, mientras que la base y la espalda ancha están confeccionadas en encaje, ofreciendo un toque de sensualidad y control en la zona de la espalda. Con un cubrimiento del busto de 3/4 y realce bajo, este sostén proporciona un soporte adecuado. Los tirantes anchos y ajustables aseguran un mayor soporte y comodidad durante todo el día.<pCuidados de la prenda:</p>_x000D_ <p>-_x000D_ Lavar a mano con agua fría para mantener la calidad._x000D_ - Evitar blanqueador, remojo y lavado en seca_x000D_ - Secar colgado y a la sombra, sin retorcer ni usar secadora._x000D_ <p>Sugerencias adicionales:</p>_x000D_ <ol>1. Al lavar, usar detergente suave y evitar fricción.</ol> | D360: Silueta ajustada que realza las curvas Escote cruzado en el frente con canal Cargaderas ajustables para mejor ajuste | E360: <body><h2>Brasier copa 3/4 x2 und en microfibra y encaje</h2><br/><p>Conoce nuestro conjunto de brasieres en paquetería x2, diseñados en estilo bustier para brindarte comodidad y un ajuste favorecedor. Las copas están elaboradas en microfibra para una sensación suave y cómoda, mientras que la base y la espalda ancha están confeccionadas en encaje, ofreciendo un toque de sensualidad y control en la zona de la espalda.</p><br/><p>Con un cubrimiento del busto de 3/4 y realce bajo, este sostén proporciona un soporte adecuado. Los tirantes anchos y ajustables aseguran un mayor soporte y comodidad durante todo el día.<pCuidados de la prenda:</p>_x000D_ <p>-_x000D_ Lavar a mano con agua fría para mantener la calidad._x000D_ - Evitar blanqueador, remojo y lavado en seca_x000D_ - Secar colgado y a la sombra, sin retorcer ni usar secadora._x000D_ <p>Sugerencias adicionales:</p>_x000D_ <ol>1. Al lavar, usar detergente suave y evitar fricción.</ol></body>
A361: =VLOOKUP(B361,Sheet1!A:B,2,FALSE) -> 223 | B361: Panty microfibra paquete x4 | C361: Ideal para moldear suavemente la zona del abdomen, este panty de poliamida ofrece un estilo moderno con cobertura media y elasticidad para moverte con total comodidad.<br><br>_x000D__x000D_ _x000D__x000D_ <strong>Características destacadas</strong><br>_x000D__x000D_ <strong>Diseño de talle alto:</strong> Favorece la zona del abdomen y aporta un ajuste moderno.<br>_x000D__x000D_ <strong>Tecnología sin costuras en los costados:</strong> Evita marcas y proporciona libertad de movimiento.<br>_x000D__x000D_ <strong>Refuerzo en algodón:</strong> Asegura frescura y transpirabilidad en la zona íntima.<br><br><br><strong>Cuidados de la prenda:</strong><br>_x000D__x000D_ - Lavar a mano o en lavadora en ciclo delicado.<br>_x000D__x000D_ - Evitar agua caliente, blanqueador, remojo y lavado en seco.<br>_x000D__x000D_ - Secar colgado y a la sombra, sin planchar ni usar secadora.<br> _x000D__x000D_ <strong>Sugerencias adicionales:</strong><br>_x000D__x000D_ 1. Al lavar, usar detergente suave y evitar fricción.<br>_x000D__x000D_ 2. Evitar superficies ásperas y almacenar en lugar fresco y seco. | D361: Silueta ajustada que realza las curvas Escote cruzado en el frente con canal Cargaderas ajustables para mejor ajuste | E361: <body><h2>Panty microfibra paquete x4</h2><br/><p>Ideal para moldear suavemente la zona del abdomen, este panty de poliamida ofrece un estilo moderno con cobertura media y elasticidad para moverte con total comodidad.</p><br/><ul><li>Silueta ajustada: Favorece la zona del abdomen y aporta un ajuste moderno.</li><li>Tecnología sin costuras en los costados: Evita marcas y proporciona libertad de movimiento.</li><li>Refuerzo en algodón: Asegura frescura y transpirabilidad en la zona íntima.</li></ul><br/><p>Cuidados de la prenda:</p><ul><li>Lavar a mano o en lavadora en ciclo delicado.</li><li>Evitar agua caliente, blanqueador, remojo y lavado en seco.</li><li>Secer colgado y a la sombra, sin planchar ni usar secadora.</li></ul><br/><p>Sugerencias adicionales:</p><ul><li>Al lavar, usar detergente suave y evitar fricción.</li><li>Evitar superficies ásperas y almacenar en lugar fresco y seco.</li></ul></body>
A362: =VLOOKUP(B362,Sheet1!A:B,2,FALSE) -> 488 | B362: Hipster invisible en microfibra paquete x5 | C362: <p>Cuidados de la prenda:</p>_x000D_ <p>- Lavar a mano o en lavadora en ciclo delicado.</p>_x000D_ <p>- Evitar agua caliente, blanqueador, remojo y lavado en seco.</p>_x000D_ <p>- Secar colgado y a la sombra, sin planchar ni usar secadora.</p>_x000D_ <p>Sugerencias adicionales:</p>_x000D_ <ul><li>Al lavar, usar detergente suave y evitar fricción.</li><li>Evitar superficies ásperas y almacenar en lugar fresco y seco.</li></ul> | D362: <strong>Silueta ajustada:</strong> Realza las curvas <strong>Escote cruzado:</strong> Agrega sofisticación <strong>Cargaderas ajustables:</strong> Para mayor comodidad | E362: <ul><li>Al lavar, usar detergente suave y evitar fricción.</li><li>Evitar superficies ásperas y almacenar en lugar fresco y seco.</li></ul>
A363: =VLOOKUP(B363,Sheet1!A:B,2,FALSE) -> 323 | B363: Paquete x2 panty hipster para niña en algodón | C363: ¡COLECCIÓN BACK TO SCHOOL! Para el día a día de nuestras niñas en el colegio, te recomendamos nuestro panty tipo hipster en algodón transpirable y suave. Le brindara comodidad y rescura en cada momento, además de tener colores ideales para el uso con el uniforme escolar. Su talle es medio y refuerzo en algodón.<br><strong>Cuidados de la prenda:</strong><br>_x000D_ - Lavar a mano o en lavadora en ciclo delicado.<br>_x000D_ - Evitar agua caliente, blanqueador, remojo y lavado en seco.<br>_x000D_ - Secar colgado y a la sombra, sin planchar ni usar secadora.<br> _x000D_ <strong>Sugerencias adicionales:</strong><br>_x000D_ 1. Al lavar, usar detergente suave y evitar fricción.<br>_x000D_ 2. Evitar superficies ásperas y almacenar en lugar fresco y seco. | D363: Silueta ajustada que realza las curvas Escote cruzado en el frente con canal Cargaderas ajustables para mejor ajuste | E363: <body><h2>Paquete x2 panty hipster para niña en algodón</h2><br/><p style='text-align:justify'>¡COLECCIÓN BACK TO SCHOOL! Para el día a día de nuestras niñas en el colegio, te recomendamos nuestro panty tipo hipster en algodón transpirable y suave. Le brindara comodidad y rescura en cada momento, además de tener colores ideales para el uso con el uniforme escolar. Su talle es medio y refuerzo en algodón.<br><strong>Cuidados de la prenda:</strong><br>_x000D_ - Lavar a mano o en lavadora en ciclo delicado.<br>_x000D_ - Evitar agua caliente, blanqueador, remojo y lavado en seco.<br>_x000D_ - Secar colgado y a la sombra, sin planchar ni usar secadora.<br> _x000D_ <strong>Sugerencias adicionales:</strong><br>_x000D_ 1. Al lavar, usar detergente suave y evitar fricción.<br>_x000D_ 2. Evitar superficies ásperas y almacenar en lugar fresco y seco.</p></body>
A364: =VLOOKUP(B364,Sheet1!A:B,2,FALSE) -> 253 | B364: Vestido de baño dos piezas para niña | C364: Este conjunto de vestido y panty playero está hecho para las niñas. El top es cómodo y fresco, con soporte elástico en la base y tiras cruzadas en la espalda. El panty tipo bóxer ofrece un cubrimiento óptimo en las piernas. ¡Eleva tu estilo playero y prepárate para vivir aventuras llenas de diversión! | D364: Silueta ajustada que realza las curvas Escote cruzado en el frente con canal Cargaderas ajustables para mejor ajuste | E364: <body><h2>Vestido de baño dos piezas para niña</h2><br/><p style='text-align:justify'>Este conjunto de vestido y panty playero está hecho para las niñas. El top es cómodo y fresco, con soporte elástico en la base y tiras cruzadas en la espalda. El panty tipo bóxer ofrece un cubrimiento óptimo en las piernas. ¡Eleva tu estilo playero y prepárate para vivir aventuras llenas de diversión!</p><br/><h4>Cuidados de la prenda:</h4><ul><li>Lavar a mano con agua fría máx. 30º.</li><li>No usar blanqueador ni dejar en remojo.</li><li>No lavar en seco.</li><li>Secar colgado a la sombra.</li><li>No planchar ni usar secadora.</li><li>No retorcer.</li></ul><h4>Sugerencias adicionales:</h4><ul><li>Enjuagar después de usar.</li><li>No usar suavizante.</li><li>Eviar el secado directo al sol.</li><li>Almacenar en lugar seco y ventilado.</li></ul></body>
A365: =VLOOKUP(B365,Sheet1!A:B,2,FALSE) -> 252 | B365: Brasier en microfibra copa "c" individual | C365: <p>Nuestro brasier de microfibra está diseñado para realzar tu belleza natural con una copa "C" de cubrimiento 3/4. Los tirantes multiusos anchos añaden versatilidad a tu estilo, permitiéndote adaptarlos según tus preferencias.<br><br><strong>Características Destacadas:</strong><br><br><strong>Realce Natural:</strong> Copa "C" de cubrimiento 3/4 para una apariencia natural y elegante.<br><strong>Versatilidad en Estilo:</strong> Tirantes multiusos anchos para adaptarlos según tus preferencias.<br><strong>Comodidad Duradera: </strong>Elaborado en microfibra suave para una sensación delicada en la piel.</p>_x000D_ _x000D_ <p><strong>Cuidados de la prenda:</strong><br>_x000D_ - Lavar a mano con agua fría para mantener la calidad.<br>_x000D_ - Evitar blanqueador, remojo y lavado en seco.<br>_x000D_ - Secar colgado y a la sombra, sin retorcer ni usar secadora.</p>_x000D_ <p><strong>Sugerencias adicionales:</strong><br>_x000D_ 1. Al lavar, usar detergente suave y evitar fricción.<br>_x000D_ 2. Evitar superficies ásperas y almacenar en lugar fresco y seco.</p>_x000D_ <ul>_x000D_ <li>Silueta ajustada que realza las curvas</li>_x000D_ <li>Copa "C" de cubrimiento 3/4 para una apariencia natural</li>_x000D_ <li>Tirantes multiusos anchos para adaptar estilo</li>_x000D_ </ul> | D365: Silueta ajustada que realza las curvas Copa "C" de cubrimiento 3/4 para una apariencia natural Tirantes multiusos anchos para adaptar estilo | E365: <body><h2>Brasier en microfibra copa "c" individual</h2><br/><p>Nuestro brasier de microfibra está diseñado para realzar tu belleza natural con una copa …</p><br/><strong>Características Destacadas:</strong><br/><ul><li>Silueta ajustada que realza las curvas</li><li>Copa "C" de cubrimiento 3/4 para una apariencia natural</li><li>Tirantes multiusos anchos para adaptar estilo</li></ul><p><strong>Cuidados de la prenda:</strong><br/>- Lavar a mano con agua fría para mantener la calidad.<br/>- Evitar blanqueador, remojo y lavado en seco.<br/>- Secar colgado y a la sombra, sin retorcer ni usar secadora.</p><p>Sugerencias adicionales:<br/>1. Al lavar, usar detergente suave y evitar fricción.<br/>2. Evitar superficies ásperas y almacenar en lugar fresco y seco.</p></body>
